Workbook
Name Slicer_City: #N/A
Name Slicer_Test_Name: #N/A
Name Slicer_Zone: #N/A

Sheet Zone-wise Performance
A3: Zone | B3: Average of Total Score
A4: East | B4: 239.66667
A5: North | B5: 208.77778
A6: South | B6: 222.20833
A7: West | B7: 207.0625
A8: Grand Total | B8: 213.45455

Sheet City-wise Top Students
A3: City | B3: Max of Total Score
A4: Bangalore | B4: 254
A5: Chennai | B5: 261
A6: HYDERABAD | B6: 259
A7: PUNE | B7: 264
A8: Grand Total | B8: 264

Sheet Subject-wise Performance
A3: Average of Maths | B3: Average of Physics | C3: Average of Chemistry
A4: 73.164474 | B4: 70.480263 | C4: 72.828947

Sheet Attendance vs Performance
A3: Attendance_Range | B3: Average of Average Score
A4: 60 | B4: 78
A5: 70 | B5: 71.184211
A6: 80 | B6: 70.848958
A7: 90 | B7: 74.503401
A8: Grand Total | B8: 72.157895

Sheet Dashboard

Sheet Sheet2
A3: Test_Name | B3: Average of Average Score
A4: Test1 | B4: 73.394558
A5: Test2 | B5: 70.261905
A6: Test3 | B6: 72.627778
A7: Tset1 | B7: 63
A8: Grand Total | B8: 72.157895

Sheet Sheet1
A1: Student_ID | B1: Name | C1: City | D1: Zone | E1: Maths | F1: Physics | G1: Chemistry | H1: Attendance | I1: Test_Name | J1: Standard City | K1: Standard Attendance | L1: Correct_Zone | M1: Total Score | N1: Average Score | O1: Performance Category | P1: Attendance_Percent | Q1: Attendance_Range
A2: 101 | B2: Rahul | C2: Bangalore | D2: South | E2: 78 | F2: 74 | G2: 86 | H2: 0.9 | I2: Test1 | J2: =UPPER(C6) -> BANGALORE | K2: =VALUE(SUBSTITUTE(H2,"%","")) -> 0.9 | L2: =VLOOKUP(C2, Mapping!A:B, 2, FALSE) -> South | M2: =E2 + F2 + G2 -> 238 | N2: =AVERAGE(E2, F2, G2) -> 79.333333 | O2: =IF(N2>80,"Top",IF(N2>60,"Average","Low")) -> Average | P2: =K2*100 -> 90 | Q2: =FLOOR(P2,10) -> 90
A3: 102 | B3: Dinesh | C3: HYDERABAD | D3: West | E3: 90 | F3: 86 | G3: 74 | H3: 0.82 | I3: Test1 | J3: =UPPER(C3) -> HYDERABAD | K3: =VALUE(SUBSTITUTE(H3,"%","")) -> 0.82 | L3: =VLOOKUP(C3, Mapping!A:B, 2, FALSE) -> South | M3: =E3 + F3 + G3 -> 250 | N3: =AVERAGE(E3, F3, G3) -> 83.333333 | O3: =IF(N3>80,"Top",IF(N3>60,"Average","Low")) -> Top | P3: =K3*100 -> 82 | Q3: =FLOOR(P3,10) -> 80
A4: 103 | B4: Deepika | C4: HYDERABAD | D4: West | E4: 66 | F4: 78 | G4: 90 | H4: seventy nine | I4: Test1 | J4: =UPPER(C4) -> HYDERABAD | K4: 0.79 | L4: =VLOOKUP(C4, Mapping!A:B, 2, FALSE) -> South | M4: =E4 + F4 + G4 -> 234 | N4: =AVERAGE(E4, F4, G4) -> 78 | O4: =IF(N4>80,"Top",IF(N4>60,"Average","Low")) -> Average | P4: =K4*100 -> 79 | Q4: =FLOOR(P4,10) -> 70
A5: 104 | B5: Soumya | C5: Bangalore | D5: North | E5: 52 | F5: 59 | G5: 78 | H5: 0.87 | I5: Test1 | J5: =UPPER(C6) -> BANGALORE | K5: 0.87 | L5: =VLOOKUP(C5, Mapping!A:B, 2, FALSE) -> South | M5: =E5 + F5 + G5 -> 189 | N5: =AVERAGE(E5, F5, G5) -> 63 | O5: =IF(N5>80,"Top",IF(N5>60,"Average","Low")) -> Average | P5: =K5*100 -> 87 | Q5: =FLOOR(P5,10) -> 80
A6: 105 | B6: Ram | C6: BANGALORE | D6: South | E6: 59 | F6: 90 | G6: 59 | H6: 0.85 | I6: Test1 | J6: =UPPER(C6) -> BANGALORE | K6: 0.85 | L6: =VLOOKUP(C6, Mapping!A:B, 2, FALSE) -> South | M6: =E6 + F6 + G6 -> 208 | N6: =AVERAGE(E6, F6, G6) -> 69.333333 | O6: =IF(N6>80,"Top",IF(N6>60,"Average","Low")) -> Average | P6: =K6*100 -> 85 | Q6: =FLOOR(P6,10) -> 80
A7: 106 | B7: Sam | C7: Chennai | D7: East | E7: 86 | F7: 78 | G7: 66 | H7: 0.79 | I7: Test1 | J7: =UPPER(C7) -> CHENNAI | K7: 0.79 | L7: =VLOOKUP(C7, Mapping!A:B, 2, FALSE) -> South | M7: =E7 + F7 + G7 -> 230 | N7: =AVERAGE(E7, F7, G7) -> 76.666667 | O7: =IF(N7>80,"Top",IF(N7>60,"Average","Low")) -> Average | P7: =K7*100 -> 79 | Q7: =FLOOR(P7,10) -> 70
A8: 107 | B8: Jam | C8: Bangalore | D8: South | E8: 90 | F8: 66 | G8: 90 | H8: eighty five | I8: Test1 | J8: =UPPER(C8) -> BANGALORE | K8: 0.85 | L8: =VLOOKUP(C8, Mapping!A:B, 2, FALSE) -> South | M8: =E8 + F8 + G8 -> 246 | N8: =AVERAGE(E8, F8, G8) -> 82 | O8: =IF(N8>80,"Top",IF(N8>60,"Average","Low")) -> Top | P8: =K8*100 -> 85 | Q8: =FLOOR(P8,10) -> 80
A9: 108 | B9: Sai | C9: hyderabad | D9: West | E9: 59 | F9: 66 | G9: 74 | H9: 0.82 | I9: Test1 | J9: =UPPER(C9) -> HYDERABAD | K9: 0.82 | L9: =VLOOKUP(C9, Mapping!A:B, 2, FALSE) -> South | M9: =E9 + F9 + G9 -> 199 | N9: =AVERAGE(E9, F9, G9) -> 66.333333 | O9: =IF(N9>80,"Top",IF(N9>60,"Average","Low")) -> Average | P9: =K9*100 -> 82 | Q9: =FLOOR(P9,10) -> 80
A10: 109 | B10: Diya | C10: BANGALORE | D10: East | E10: 78 | F10: 86 | G10: 59 | H10: seventy nine | I10: Test1 | J10: =UPPER(C10) -> BANGALORE | K10: 0.79 | L10: =VLOOKUP(C10, Mapping!A:B, 2, FALSE) -> South | M10: =E10 + F10 + G10 -> 223 | N10: =AVERAGE(E10, F10, G10) -> 74.333333 | O10: =IF(N10>80,"Top",IF(N10>60,"Average","Low")) -> Average | P10: =K10*100 -> 79 | Q10: =FLOOR(P10,10) -> 70
A11: 119 | B11: Ramya | C11: Bangalore | D11: West | E11: 66 | F11: 59 | G11: 78 | H11: 0.9 | I11: Test1 | J11: =UPPER(C11) -> BANGALORE | K11: 0.9 | L11: =VLOOKUP(C11, Mapping!A:B, 2, FALSE) -> South | M11: =E11 + F11 + G11 -> 203 | N11: =AVERAGE(E11, F11, G11) -> 67.666667 | O11: =IF(N11>80,"Top",IF(N11>60,"Average","Low")) -> Average | P11: =K11*100 -> 90 | Q11: =FLOOR(P11,10) -> 90
A12: 111 | B12: Hari | C12: Bangalore | D12: West | E12: 86 | F12: 90 | G12: 66 | H12: ninety two | I12: Test1 | J12: =UPPER(C6) -> BANGALORE | K12: 0.92 | L12: =VLOOKUP(C12, Mapping!A:B, 2, FALSE) -> South | M12: =E12 + F12 + G12 -> 242 | N12: =AVERAGE(E12, F12, G12) -> 80.666667 | O12: =IF(N12>80,"Top",IF(N12>60,"Average","Low")) -> Top | P12: =K12*100 -> 92 | Q12: =FLOOR(P12,10) -> 90
A13: 112 | B13: Priya | C13: Chennai | D13: South | E13: 90 | F13: 66 | G13: 90 | H13: 0.85 | I13: Test1 | J13: =UPPER(C13) -> CHENNAI | K13: 0.85 | L13: =VLOOKUP(C13, Mapping!A:B, 2, FALSE) -> South | M13: =E13 + F13 + G13 -> 246 | N13: =AVERAGE(E13, F13, G13) -> 82 | O13: =IF(N13>80,"Top",IF(N13>60,"Average","Low")) -> Top | P13: =K13*100 -> 85 | Q13: =FLOOR(P13,10) -> 80
A14: 113 | B14: Harthik | C14: Chennai | D14: West | E14: 59 | F14: 78 | G14: 86 | H14: 0.79 | I14: Test1 | J14: =UPPER(C14) -> CHENNAI | K14: 0.79 | L14: =VLOOKUP(C14, Mapping!A:B, 2, FALSE) -> South | M14: =E14 + F14 + G14 -> 223 | N14: =AVERAGE(E14, F14, G14) -> 74.333333 | O14: =IF(N14>80,"Top",IF(N14>60,"Average","Low")) -> Average | P14: =K14*100 -> 79 | Q14: =FLOOR(P14,10) -> 70
A15: 114 | B15: Deepa | C15: Bangalore | D15: North | E15: 66 | F15: 74 | G15: 59 | H15: 0.95 | I15: Test1 | J15: =UPPER(C15) -> BANGALORE | K15: 0.95 | L15: =VLOOKUP(C15, Mapping!A:B, 2, FALSE) -> South | M15: =E15 + F15 + G15 -> 199 | N15: =AVERAGE(E15, F15, G15) -> 66.333333 | O15: =IF(N15>80,"Top",IF(N15>60,"Average","Low")) -> Average | P15: =K15*100 -> 95 | Q15: =FLOOR(P15,10) -> 90
A16: 115 | B16: Deepthi | C16: Chennai | D16: West | E16: 86 | F16: 90 | G16: 78 | H16: 0.85 | I16: Test1 | J16: =UPPER(C16) -> CHENNAI | K16: 0.85 | L16: =VLOOKUP(C16, Mapping!A:B, 2, FALSE) -> South | M16: =E16 + F16 + G16 -> 254 | N16: =AVERAGE(E16, F16, G16) -> 84.666667 | O16: =IF(N16>80,"Top",IF(N16>60,"Average","Low")) -> Top | P16: =K16*100 -> 85 | Q16: =FLOOR(P16,10) -> 80
A17: 116 | B17: Fathima | C17: Bangalore | D17: South | E17: 78 | F17: 86 | G17: 86 | H17: 0.82 | I17: Test1 | J17: =UPPER(C6) -> BANGALORE | K17: 0.82 | L17: =VLOOKUP(C17, Mapping!A:B, 2, FALSE) -> South | M17: =E17 + F17 + G17 -> 250 | N17: =AVERAGE(E17, F17, G17) -> 83.333333 | O17: =IF(N17>80,"Top",IF(N17>60,"Average","Low")) -> Top | P17: =K17*100 -> 82 | Q17: =FLOOR(P17,10) -> 80
A18: 106 | B18: Sri | C18: Bangalore | D18: North | E18: 90 | F18: 66 | G18: 66 | H18: eighty five | I18: Test1 | J18: =UPPER(C18) -> BANGALORE | K18: 0.85 | L18: =VLOOKUP(C18, Mapping!A:B, 2, FALSE) -> South | M18: =E18 + F18 + G18 -> 222 | N18: =AVERAGE(E18, F18, G18) -> 74 | O18: =IF(N18>80,"Top",IF(N18>60,"Average","Low")) -> Average | P18: =K18*100 -> 85 | Q18: =FLOOR(P18,10) -> 80
A19: 118 | B19: Satya | C19: Bangalore | D19: West | E19: 59 | F19: 86 | G19: 90 | H19: 0.95 | I19: Test1 | J19: =UPPER(C19) -> BANGALORE | K19: 0.95 | L19: =VLOOKUP(C19, Mapping!A:B, 2, FALSE) -> South | M19: =E19 + F19 + G19 -> 235 | N19: =AVERAGE(E19, F19, G19) -> 78.333333 | O19: =IF(N19>80,"Top",IF(N19>60,"Average","Low")) -> Average | P19: =K19*100 -> 95 | Q19: =FLOOR(P19,10) -> 90
A20: 119 | B20: Hema | C20: hyderabad | D20: East | E20: 66 | F20: 59 | G20: 78 | H20: 0.87 | I20: Test1 | J20: =UPPER(C20) -> HYDERABAD | K20: 0.87 | L20: =VLOOKUP(C20, Mapping!A:B, 2, FALSE) -> South | M20: =E20 + F20 + G20 -> 203 | N20: =AVERAGE(E20, F20, G20) -> 67.666667 | O20: =IF(N20>80,"Top",IF(N20>60,"Average","Low")) -> Average | P20: =K20*100 -> 87 | Q20: =FLOOR(P20,10) -> 80
A21: 120 | B21: Hrushi | C21: BANGALORE | D21: West | E21: 74 | F21: 74 | G21: 59 | H21: ninety two | I21: Test1 | J21: =UPPER(C21) -> BANGALORE | K21: 0.92 | L21: =VLOOKUP(C21, Mapping!A:B, 2, FALSE) -> South | M21: =E21 + F21 + G21 -> 207 | N21: =AVERAGE(E21, F21, G21) -> 69 | O21: =IF(N21>80,"Top",IF(N21>60,"Average","Low")) -> Average | P21: =K21*100 -> 92 | Q21: =FLOOR(P21,10) -> 90
A22: 121 | B22: Henu | C22: Chennai | D22: North | E22: 90 | F22: 78 | G22: 66 | H22: 0.79 | I22: Test1 | J22: =UPPER(C22) -> CHENNAI | K22: 0.79 | L22: =VLOOKUP(C22, Mapping!A:B, 2, FALSE) -> South | M22: =E22 + F22 + G22 -> 234 | N22: =AVERAGE(E22, F22, G22) -> 78 | O22: =IF(N22>80,"Top",IF(N22>60,"Average","Low")) -> Average | P22: =K22*100 -> 79 | Q22: =FLOOR(P22,10) -> 70
A23: 106 | B23: Avi | C23: Bangalore | D23: West | E23: 86 | F23: 52 | G23: 90 | H23: 0.85 | I23: Test1 | J23: =UPPER(C23) -> BANGALORE | K23: 0.85 | L23: =VLOOKUP(C23, Mapping!A:B, 2, FALSE) -> South | M23: =E23 + F23 + G23 -> 228 | N23: =AVERAGE(E23, F23, G23) -> 76 | O23: =IF(N23>80,"Top",IF(N23>60,"Average","Low")) -> Average | P23: =K23*100 -> 85 | Q23: =FLOOR(P23,10) -> 80
A24: 111 | B24: Pavi | C24: Bangalore | D24: South | E24: 66 | F24: 90 | G24: 74 | H24: 0.82 | I24: Test1 | J24: =UPPER(C6) -> BANGALORE | K24: 0.82 | L24: =VLOOKUP(C24, Mapping!A:B, 2, FALSE) -> South | M24: =E24 + F24 + G24 -> 230 | N24: =AVERAGE(E24, F24, G24) -> 76.666667 | O24: =IF(N24>80,"Top",IF(N24>60,"Average","Low")) -> Average | P24: =K24*100 -> 82 | Q24: =FLOOR(P24,10) -> 80
A25: 124 | B25: Sheeba | C25: BANGALORE | D25: West | E25: 74 | F25: 66 | G25: 78 | H25: 0.9 | I25: Test1 | J25: =UPPER(C25) -> BANGALORE | K25: 0.9 | L25: =VLOOKUP(C25, Mapping!A:B, 2, FALSE) -> South | M25: =E25 + F25 + G25 -> 218 | N25: =AVERAGE(E25, F25, G25) -> 72.666667 | O25: =IF(N25>80,"Top",IF(N25>60,"Average","Low")) -> Average | P25: =K25*100 -> 90 | Q25: =FLOOR(P25,10) -> 90
A26: 133 | B26: Nis | C26: Bangalore | D26: East | E26: 78 | F26: 86 | G26: 90 | H26: seventy nine | I26: Test1 | J26: =UPPER(C6) -> BANGALORE | K26: 0.79 | L26: =VLOOKUP(C26, Mapping!A:B, 2, FALSE) -> South | M26: =E26 + F26 + G26 -> 254 | N26: =AVERAGE(E26, F26, G26) -> 84.666667 | O26: =IF(N26>80,"Top",IF(N26>60,"Average","Low")) -> Top | P26: =K26*100 -> 79 | Q26: =FLOOR(P26,10) -> 70
A27: 108 | B27: Blessy | C27: Chennai | D27: North | E27: 59 | F27: 59 | G27: 66 | H27: 0.79 | I27: Test1 | J27: =UPPER(C27) -> CHENNAI | K27: 0.79 | L27: =VLOOKUP(C27, Mapping!A:B, 2, FALSE) -> South | M27: =E27 + F27 + G27 -> 184 | N27: =AVERAGE(E27, F27, G27) -> 61.333333 | O27: =IF(N27>80,"Top",IF(N27>60,"Average","Low")) -> Average | P27: =K27*100 -> 79 | Q27: =FLOOR(P27,10) -> 70
A28: 127 | B28: Siri | C28: hyderabad | D28: South | E28: 66 | F28: 78 | G28: 90 | H28: 0.85 | I28: Test1 | J28: =UPPER(C28) -> HYDERABAD | K28: 0.85 | L28: =VLOOKUP(C28, Mapping!A:B, 2, FALSE) -> South | M28: =E28 + F28 + G28 -> 234 | N28: =AVERAGE(E28, F28, G28) -> 78 | O28: =IF(N28>80,"Top",IF(N28>60,"Average","Low")) -> Average | P28: =K28*100 -> 85 | Q28: =FLOOR(P28,10) -> 80
A29: 130 | B29: Chintu | C29: Bangalore | D29: West | E29: 90 | F29: 52 | G29: 59 | H29: 0.82 | I29: Test1 | J29: =UPPER(C6) -> BANGALORE | K29: 0.82 | L29: =VLOOKUP(C29, Mapping!A:B, 2, FALSE) -> South | M29: =E29 + F29 + G29 -> 201 | N29: =AVERAGE(E29, F29, G29) -> 67 | O29: =IF(N29>80,"Top",IF(N29>60,"Average","Low")) -> Average | P29: =K29*100 -> 82 | Q29: =FLOOR(P29,10) -> 80
A30: 106 | B30: Ramesh | C30: Bangalore | D30: North | E30: 74 | F30: 90 | G30: 78 | H30: 0.79 | I30: Test1 | J30: =UPPER(C30) -> BANGALORE | K30: 0.79 | L30: =VLOOKUP(C30, Mapping!A:B, 2, FALSE) -> South | M30: =E30 + F30 + G30 -> 242 | N30: =AVERAGE(E30, F30, G30) -> 80.666667 | O30: =IF(N30>80,"Top",IF(N30>60,"Average","Low")) -> Top | P30: =K30*100 -> 79 | Q30: =FLOOR(P30,10) -> 70
A31: 130 | B31: Suresh | C31: Bangalore | D31: West | E31: 78 | F31: 52 | G31: 66 | H31: eighty five | I31: Test1 | J31: =UPPER(C6) -> BANGALORE | K31: 0.85 | L31: =VLOOKUP(C31, Mapping!A:B, 2, FALSE) -> South | M31: =E31 + F31 + G31 -> 196 | N31: =AVERAGE(E31, F31, G31) -> 65.333333 | O31: =IF(N31>80,"Top",IF(N31>60,"Average","Low")) -> Average | P31: =K31*100 -> 85 | Q31: =FLOOR(P31,10) -> 80
A32: 131 | B32: Prem | C32: Bangalore | D32: North | E32: 59 | F32: 52 | G32: 90 | H32: 0.87 | I32: Test1 | J32: =UPPER(C32) -> BANGALORE | K32: 0.87 | L32: =VLOOKUP(C32, Mapping!A:B, 2, FALSE) -> South | M32: =E32 + F32 + G32 -> 201 | N32: =AVERAGE(E32, F32, G32) -> 67 | O32: =IF(N32>80,"Top",IF(N32>60,"Average","Low")) -> Average | P32: =K32*100 -> 87 | Q32: =FLOOR(P32,10) -> 80
A33: 132 | B33: Guna | C33: BANGALORE | D33: South | E33: 52 | F33: 78 | G33: 74 | H33: 0.9 | I33: Test1 | J33: =UPPER(C6) -> BANGALORE | K33: 0.9 | L33: =VLOOKUP(C33, Mapping!A:B, 2, FALSE) -> South | M33: =E33 + F33 + G33 -> 204 | N33: =AVERAGE(E33, F33, G33) -> 68 | O33: =IF(N33>80,"Top",IF(N33>60,"Average","Low")) -> Average | P33: =K33*100 -> 90 | Q33: =FLOOR(P33,10) -> 90
A34: 133 | B34: Anudeep | C34: Chennai | D34: West | E34: 74 | F34: 59 | G34: 59 | H34: 0.82 | I34: Test1 | J34: =UPPER(C34) -> CHENNAI | K34: 0.82 | L34: =VLOOKUP(C34, Mapping!A:B, 2, FALSE) -> South | M34: =E34 + F34 + G34 -> 192 | N34: =AVERAGE(E34, F34, G34) -> 64 | O34: =IF(N34>80,"Top",IF(N34>60,"Average","Low")) -> Average | P34: =K34*100 -> 82 | Q34: =FLOOR(P34,10) -> 80
A35: 106 | B35: Vishal | C35: Bangalore | D35: West | E35: 66 | F35: 66 | G35: 90 | H35: 0.95 | I35: Test1 | J35: =UPPER(C6) -> BANGALORE | K35: 0.95 | L35: =VLOOKUP(C35, Mapping!A:B, 2, FALSE) -> South | M35: =E35 + F35 + G35 -> 222 | N35: =AVERAGE(E35, F35, G35) -> 74 | O35: =IF(N35>80,"Top",IF(N35>60,"Average","Low")) -> Average | P35: =K35*100 -> 95 | Q35: =FLOOR(P35,10) -> 90
A36: 119 | B36: Banthi | C36: Chennai | D36: East | E36: 59 | F36: 90 | G36: 78 | H36: seventy nine | I36: Test1 | J36: =UPPER(C36) -> CHENNAI | K36: 0.79 | L36: =VLOOKUP(C36, Mapping!A:B, 2, FALSE) -> South | M36: =E36 + F36 + G36 -> 227 | N36: =AVERAGE(E36, F36, G36) -> 75.666667 | O36: =IF(N36>80,"Top",IF(N36>60,"Average","Low")) -> Average | P36: =K36*100 -> 79 | Q36: =FLOOR(P36,10) -> 70
A37: 136 | B37: Nani | C37: hyderabad | D37: North | E37: 78 | F37: 52 | G37: 59 | H37: 0.79 | I37: Test1 | J37: =UPPER(C37) -> HYDERABAD | K37: 0.79 | L37: =VLOOKUP(C37, Mapping!A:B, 2, FALSE) -> South | M37: =E37 + F37 + G37 -> 189 | N37: =AVERAGE(E37, F37, G37) -> 63 | O37: =IF(N37>80,"Top",IF(N37>60,"Average","Low")) -> Average | P37: =K37*100 -> 79 | Q37: =FLOOR(P37,10) -> 70
A38: 146 | B38: Pinky | C38: BANGALORE | D38: South | E38: 90 | F38: 66 | G38: 66 | H38: 0.9 | I38: Test1 | J38: =UPPER(C38) -> BANGALORE | K38: 0.9 | L38: =VLOOKUP(C38, Mapping!A:B, 2, FALSE) -> South | M38: =E38 + F38 + G38 -> 222 | N38: =AVERAGE(E38, F38, G38) -> 74 | O38: =IF(N38>80,"Top",IF(N38>60,"Average","Low")) -> Average | P38: =K38*100 -> 90 | Q38: =FLOOR(P38,10) -> 90
A39: 138 | B39: Chanti | C39: Bangalore | D39: East | E39: 74 | F39: 78 | G39: 90 | H39: ninety two | I39: Test1 | J39: =UPPER(C39) -> BANGALORE | K39: 0.92 | L39: =VLOOKUP(C39, Mapping!A:B, 2, FALSE) -> South | M39: =E39 + F39 + G39 -> 242 | N39: =AVERAGE(E39, F39, G39) -> 80.666667 | O39: =IF(N39>80,"Top",IF(N39>60,"Average","Low")) -> Top | P39: =K39*100 -> 92 | Q39: =FLOOR(P39,10) -> 90
A40: 139 | B40: Prasad | C40: PUNE | D40: West | E40: 66 | F40: 66 | G40: 52 | H40: 0.79 | I40: Test1 | J40: PUNE | K40: 0.79 | L40: =VLOOKUP(C40, Mapping!A:B, 2, FALSE) -> West | M40: =E40 + F40 + G40 -> 184 | N40: =AVERAGE(E40, F40, G40) -> 61.333333 | O40: =IF(N40>80,"Top",IF(N40>60,"Average","Low")) -> Average | P40: =K40*100 -> 79 | Q40: =FLOOR(P40,10) -> 70
...

Sheet Mapping
A1: City | B1: Zone
A2: BANGALORE | B2: South
A3: HYDERABAD | B3: South
A4: DELHI | B4: North
A5: MUMBAI | B5: West
A6: CHENNAI | B6: South
A7: PUNE | B7: West
